Workbook

Sheet Read Me - Methodology
A1: FemaSeed U.S. Territory Plan — v7 (ALL-MD Universe, 30-Rep Hard Cap)
A2: 2026-07-22 | Universe re-based per Megan/CEO direction. Supersedes v3; v1-v3 methodology history lives in the v3 file.
A4: SOURCES
A5: 1. Waterfall A rev1 (NATIONAL-Femasys_DataRequest_Waterfall-06222026-rev1_ME_FINAL NUMBERS.xlsx) — CANONICAL for all MD/clinic counts. Labeled columns only; stray unlabeled scratch columns excluded.
A6: 2. Femasys_Territory_Plan_v3.xlsx — territory-to-state groupings (unchanged, no geography redrawn) and census columns (Women 25-44, Income, Education), carried unchanged.
A7: Puerto Rico excluded (matches Data Request universe).
A9: UNIVERSE
A10: Plan universe: ALL MDs = 18,405 (Waterfall A rev1 TOTAL, unchanged). MSO physicians are reclassified Academic->Private, so the Academic/Private split differs from the raw waterfall: Private ALL 10,881 | Academic/Group ALL 7,524. Full tier totals unchanged: All Clinics 5,862 | >=10 MDs 4,401 | >=20 MDs 1,476. State Market Summary reproduces the full state table with the reclassification applied and highlighted; its TOTAL row ties to Waterfall A totals exactly.
A11: Source delta vs v3: v3 reconciled to 18,406. The 1-MD difference is Michigan (v3: 747; Waterfall A rev1: 746). All other states match exactly. Rev1 is the number of record.
A12: Tier definition (per source): Volume = Femara + Clomid + Letrozole + Clomiphene prescribing; >=10 and >=20 are inclusive thresholds.
A14: REP ALLOCATION — HARD CAP 30
A15: 30 reps is a hard cap; no rep-sizing math is used. Allocation (Territory Plan and Kathy tabs, blue adjustable inputs, total must stay 30; MSO reclassified to Private):
... A52: Renamed from v6. Adds: State Rankings tab in Kathy's format with full weights (state-grain census appended from the 52 ZCTA files — method validated by reproducing v3's territory census values exactly; women total 30,870,179 matches v3). MSO reclassification (Academic->Private, totals unchanged) and the 30-rep hard cap carry forward. Full reconciliation against Waterfall A rev1 re-verified: all Total-tier figures canonical (18,405 / 5,862 / 4,401 / 1,476); only documented adjustments are the MSO split move, the NV Private cell (115 = Total - Academic), and PR exclusion.

Sheet Universe Scenarios
A1: Target Universe Definition | B1: HCPs | C1: Reps @300/rep | D1: HCPs/rep @30 reps | E1: In 275-325 band @28? | F1: Status (v7)
A2: All prescribers (any volume) | B2: 18405 | C2: =MAX(1,ROUND(B2/300,0)) -> 61 | D2: =ROUND(B2/30,0) -> 614 | E2: no | F2: SELECTED — v7 universe (Waterfall A rev1 canonical; v3 showed 18,406, see Read Me)
A3: Volume >=5 (v3 selection) | B3: 8757 | C3: =MAX(1,ROUND(B3/300,0)) -> 29 | D3: =ROUND(B3/30,0) -> 292 | E3: YES (292) | F3: superseded in v7
A4: Volume >=10 | B4: 4401 | C4: =MAX(1,ROUND(B4/300,0)) -> 15 | D4: =ROUND(B4/30,0) -> 147 | E4: no
A5: Volume >=20 | B5: 1476 | C5: =MAX(1,ROUND(B5/300,0)) -> 5 | D5: =ROUND(B5/30,0) -> 49 | E5: no
A7: Universe: ALL prescribers (18,405, Waterfall A rev1) per Megan/CEO direction. Rep count is a HARD CAP of 30 (~614 MDs/rep at this universe); the 'Reps @300/rep' column is scenario context only, not a staffing proposal. Allocation of the 30 is on the Territory Plan tab; every territory is staffed.

Sheet MSO Reclassification
A1: MSO RECLASSIFICATION (per Rajiv/Kathy direction, 2026-07-22): physicians and clinics managed by MSOs (Unified Women's Healthcare, Axia) are RECLASSIFIED from Academic/Group to Private throughout this workbook. Totals are unchanged from canonical Waterfall A rev1 (18,405 MDs); only the Academic/Private split moves. Identification: the waterfall row-level Classification Basis field — every 'managed group (MSO)' row (106 physicians, 5 practice organizations). No Privia or Pediatrix rows exist in the >=10 data. LIMIT: row-level data exists only for the >=10 tier, so MSO physicians below volume 10 cannot be identified — any in the below-10 tail remain classified per the original waterfall (Academic/Group). Complete reclassification requires the data vendor re-running the waterfall.
A3: MSO organizations reclassified
A4: Practice Name | B4: Practice ID | C4: States | D4: MDs (>=10)
A5: Unified Women's Healthcare Of Texas PLLC | B5: 1952703373 | C5: TX | D5: 39
A6: Uwh Of The Carolinas, PLLC | B6: 1639506470 | C6: NC, SC | D6: 45
A7: Uwh Of Michigan PLC | B7: 1982352357 | C7: MI | D7: 11
A8: Axia Women's Health | B8: 1548215536 | C8: NJ | D8: 6
A9: Axia Women's Health | B9: 1750880118 | C9: NY, PA | D9: 5
A10: TOTAL | D10: =SUM(D5:D9) -> 106
A12: Per-state amounts moved Academic/Group -> Private (Totals unchanged)
A13: State | B13: MDs All | C13: MDs >=10 | D13: MDs >=20 | E13: Clinics All | F13: Clinics >=10 | G13: Clinics >=20
A14: MI | B14: 11 | C14: 11 | D14: 3 | E14: 1 | F14: 1 | G14: 1
A15: NC | B15: 37 | C15: 37 | D15: 14 | E15: 1 | F15: 1 | G15: 1
A16: NJ | B16: 6 | C16: 6 | D16: 2 | E16: 1 | F16: 1 | G16: 1
A17: NY | B17: 1 | C17: 1 | D17: 1 | E17: 1 | F17: 1 | G17: 1
A18: PA | B18: 4 | C18: 4 | D18: 1 | E18: 1 | F18: 1 | G18: 1
A19: SC | B19: 8 | C19: 8 | D19: 2 | E19: 1 | F19: 1 | G19: 1
A20: TX | B20: 39 | C20: 39 | D20: 12 | E20: 1 | F20: 1 | G20: 1
A21: TOTAL | B21: =SUM(B14:B20) -> 106 | C21: =SUM(C14:C20) -> 106 | D21: =SUM(D14:D20) -> 35 | E21: =SUM(E14:E20) -> 7 | F21: =SUM(F14:F20) -> 7 | G21: =SUM(G14:G20) -> 7
A23: Resulting workbook totals: All MDs 18,405 and all Total-tier counts UNCHANGED from canonical Waterfall A rev1. Split after reclassification: Private ALL 10,881 (was 10,775) | Academic/Group ALL 7,524 (was 7,630) | Private >=10 2,989 / Academic >=10 1,412 | Private >=20 1,037 / Academic >=20 439 | Private Clinics 3,654 / Academic Clinics 2,208. Clinic moves assume one clinic per distinct practice ID per state (each MSO org = 1 clinic in each state it operates).

Sheet State Market Summary
A1: Source: Waterfall A rev1 with MSO physicians/clinics RECLASSIFIED from Academic/Group to Private (see MSO Reclassification tab; adjusted cells highlighted). Totals unchanged from canonical Waterfall A. NV Private All MDs derived as Total - Academic (source shows 304, inconsistent with its own totals; see Read Me).
B2: TOTAL | H2: PRIVATE | N2: ACADEMIC/GROUP
A3: State | B3: All MDs | C3: All Clinics | D3: MDs >=10 | E3: Clinics >=10 | F3: MDs >=20 | G3: Clinics >=20 | H3: All MDs | I3: All Clinics | J3: MDs >=10 | K3: Clinics >=10 | L3: MDs >=20 | M3: Clinics >=20 | N3: All MDs | O3: All Clinics | P3: MDs >=10 | Q3: Clinics >=10 | R3: MDs >=20 | S3: Clinics >=20 | T3: Territory
A4: AK | B4: 50 | C4: 25 | D4: 14 | E4: 10 | F4: 8 | G4: 7 | H4: 37 | I4: 17 | J4: 14 | K4: 10 | L4: 8 | M4: 7 | N4: 13 | O4: 8 | P4: 0 | Q4: 0 | R4: 0 | S4: 0 | T4: T12
A5: AL | B5: 294 | C5: 113 | D5: 95 | E5: 55 | F5: 28 | G5: 22 | H5: 236 | I5: 90 | J5: 81 | K5: 46 | L5: 22 | M5: 18 | N5: 58 | O5: 23 | P5: 14 | Q5: 9 | R5: 6 | S5: 4 | T5: T18
A6: AR | B6: 180 | C6: 64 | D6: 80 | E6: 39 | F6: 30 | G6: 20 | H6: 116 | I6: 42 | J6: 60 | K6: 26 | L6: 23 | M6: 14 | N6: 64 | O6: 22 | P6: 20 | Q6: 13 | R6: 7 | S6: 6 | T6: T19
A7: AZ | B7: 273 | C7: 107 | D7: 51 | E7: 27 | F7: 19 | G7: 16 | H7: 189 | I7: 70 | J7: 40 | K7: 21 | L7: 14 | M7: 12 | N7: 84 | O7: 37 | P7: 11 | Q7: 6 | R7: 5 | S7: 4 | T7: T15
A8: CA | B8: 1499 | C8: 648 | D8: 306 | E8: 195 | F8: 106 | G8: 90 | H8: 686 | I8: 394 | J8: 147 | K8: 110 | L8: 51 | M8: 46 | N8: 813 | O8: 254 | P8: 159 | Q8: 85 | R8: 55 | S8: 44 | T8: T02
A9: CO | B9: 352 | C9: 107 | D9: 82 | E9: 37 | F9: 24 | G9: 16 | H9: 205 | I9: 57 | J9: 56 | K9: 21 | L9: 21 | M9: 13 | N9: 147 | O9: 50 | P9: 26 | Q9: 16 | R9: 3 | S9: 3 | T9: T16
A10: CT | B10: 254 | C10: 57 | D10: 32 | E10: 14 | F10: 6 | G10: 6 | H10: 175 | I10: 26 | J10: 24 | K10: 7 | L10: 4 | M10: 4 | N10: 79 | O10: 31 | P10: 8 | Q10: 7 | R10: 2 | S10: 2 | T10: T08
A11: DC | B11: 34 | C11: 16 | D11: 1 | E11: 1 | F11: 0 | G11: 0 | H11: 22 | I11: 9 | J11: 0 | K11: 0 | L11: 0 | M11: 0 | N11: 12 | O11: 7 | P11: 1 | Q11: 1 | R11: 0 | S11: 0 | T11: T22
A12: DE | B12: 28 | C12: 14 | D12: 2 | E12: 2 | F12: 1 | G12: 1 | H12: 25 | I12: 12 | J12: 1 | K12: 1 | L12: 1 | M12: 1 | N12: 3 | O12: 2 | P12: 1 | Q12: 1 | R12: 0 | S12: 0 | T12: T22
A13: FL | B13: 1107 | C13: 273 | D13: 159 | E13: 67 | F13: 46 | G13: 32 | H13: 829 | I13: 153 | J13: 120 | K13: 40 | L13: 33 | M13: 21 | N13: 278 | O13: 120 | P13: 39 | Q13: 27 | R13: 13 | S13: 11 | T13: T05
A14: GA | B14: 683 | C14: 220 | D14: 185 | E14: 86 | F14: 63 | G14: 36 | H14: 561 | I14: 171 | J14: 163 | K14: 74 | L14: 59 | M14: 33 | N14: 122 | O14: 49 | P14: 22 | Q14: 12 | R14: 4 | S14: 3 | T14: T11
A15: HI | B15: 80 | C15: 40 | D15: 19 | E15: 15 | F15: 11 | G15: 10 | H15: 36 | I15: 27 | J15: 12 | K15: 10 | L15: 8 | M15: 7 | N15: 44 | O15: 13 | P15: 7 | Q15: 5 | R15: 3 | S15: 3 | T15: T02
... A54: WY | B54: 39 | C54: 23 | D54: 7 | E54: 5 | F54: 0 | G54: 0 | H54: 17 | I54: 10 | J54: 5 | K54: 3 | L54: 0 | M54: 0 | N54: 22 | O54: 13 | P54: 2 | Q54: 2 | R54: 0 | S54: 0 | T54: T24
A55: TOTAL | B55: =SUM(B4:B54) -> 18405 | C55: =SUM(C4:C54) -> 5862 | D55: =SUM(D4:D54) -> 4401 | E55: =SUM(E4:E54) -> 2188 | F55: =SUM(F4:F54) -> 1476 | G55: =SUM(G4:G54) -> 1005 | H55: =SUM(H4:H54) -> 10881 | I55: =SUM(I4:I54) -> 3654 | ... S55: =SUM(S4:S54) -> 326

Sheet State Rankings
E1: STATE RANKINGS — Kathy's format at state grain (all 50 states + DC), for territory re-alignment. Counts from Waterfall A rev1 with MSO reclassification (via State Market Summary). Reps (J, blue) defaults to 1 per state — assign reps as you align territories and per-rep loads, Score, and Rank recalculate. Census columns (Women 25-44, Median Income, Education) aggregated ZIP->state from the 52 state ZCTA census files (33,765 ZCTAs; income population-weighted, 3,144 suppression sentinels excluded — same method as v3, validated by reproducing v3's territory values exactly). Score = Kathy's full weights: All MDs/Rep 20% / All Clinics/Rep 60% / Women 25-44 10% / Median Income 10% / Education 0%, min-max normalized. v3's census caveat applies: women totals run ~20-25% below published figures — valid for relative ranking, not absolute quotation.
J2: Weights: | K2: 20% | L2: 60% | N2: 10% | O2: 10% | P2: 0%
E3: State | F3: All MDs | G3: All Clinics | H3: All Academic/Group MDs | I3: All Academic/Group Clinics | J3: Reps | K3: All MDs/Rep | L3: All Clinics/Rep | M3: Academic Share | N3: Women 25-44 | O3: Median Income | P3: Education | Q3: Score | R3: Rank
E4: CA | F4: 1499 | G4: 648 | H4: 813 | I4: 254 | J4: 1 | K4: =IF(J4=0,"unstaffed",ROUND(F4/J4,0)) -> 1499 | L4: =IF(J4=0,"unstaffed",ROUND(G4/J4,1)) -> 648 | M4: =H4/F4 -> 0.54236157 | N4: 3698257 | O4: 97969 | P4: 34.9 | Q4: =IF(J4=0,"unstaffed",ROUND((20*100*(K4-MIN($K$4:$K$54))/(MAX($K$4:$K$54)-MIN($K$4:$K$54))+60*100*(L4-MIN($L$4:$L$54))/(MAX($L$4:$L$54)-MIN($L$4:$L$54))+10*100*(N4-MIN($N$4:$N$54))/(MAX($N$4:$N$54)-MIN($N$4:$N$54))+10*100*(O4-MIN($O$4:$O$54))/(MAX($O$4:$O$54)-MIN($O$4:$O$54)))/100,1)) -> 96.5 | R4: =IF(J4=0,"n/a",RANK(Q4,$Q$4:$Q$54)) -> 1
E5: TX | F5: 1660 | G5: 540 | H5: 546 | I5: 126 | J5: 1 | K5: =IF(J5=0,"unstaffed",ROUND(F5/J5,0)) -> 1660 | L5: =IF(J5=0,"unstaffed",ROUND(G5/J5,1)) -> 540 | M5: =H5/F5 -> 0.32891566 | N5: 3090173 | O5: 78473 | P5: 31.7 | Q5: =IF(J5=0,"unstaffed",ROUND((20*100*(K5-MIN($K$4:$K$54))/(MAX($K$4:$K$54)-MIN($K$4:$K$54))+60*100*(L5-MIN($L$4:$L$54))/(MAX($L$4:$L$54)-MIN($L$4:$L$54))+10*100*(N5-MIN($N$4:$N$54))/(MAX($N$4:$N$54)-MIN($N$4:$N$54))+10*100*(O5-MIN($O$4:$O$54))/(MAX($O$4:$O$54)-MIN($O$4:$O$54)))/100,1)) -> 82.7 | R5: =IF(J5=0,"n/a",RANK(Q5,$Q$4:$Q$54)) -> 2
E6: NY | F6: 1030 | G6: 404 | H6: 413 | I6: 148 | J6: 1 | K6: =IF(J6=0,"unstaffed",ROUND(F6/J6,0)) -> 1030 | L6: =IF(J6=0,"unstaffed",ROUND(G6/J6,1)) -> 404 | M6: =H6/F6 -> 0.40097087 | N6: 1726412 | O6: 89542 | P6: 38.3 | Q6: =IF(J6=0,"unstaffed",ROUND((20*100*(K6-MIN($K$4:$K$54))/(MAX($K$4:$K$54)-MIN($K$4:$K$54))+60*100*(L6-MIN($L$4:$L$54))/(MAX($L$4:$L$54)-MIN($L$4:$L$54))+10*100*(N6-MIN($N$4:$N$54))/(MAX($N$4:$N$54)-MIN($N$4:$N$54))+10*100*(O6-MIN($O$4:$O$54))/(MAX($O$4:$O$54)-MIN($O$4:$O$54)))/100,1)) -> 60.6 | R6: =IF(J6=0,"n/a",RANK(Q6,$Q$4:$Q$54)) -> 3
E7: FL | F7: 1107 | G7: 273 | H7: 278 | I7: 120 | J7: 1 | K7: =IF(J7=0,"unstaffed",ROUND(F7/J7,0)) -> 1107 | L7: =IF(J7=0,"unstaffed",ROUND(G7/J7,1)) -> 273 | M7: =H7/F7 -> 0.25112918 | N7: 1780020 | O7: 71602 | P7: 32.2 | Q7: =IF(J7=0,"unstaffed",ROUND((20*100*(K7-MIN($K$4:$K$54))/(MAX($K$4:$K$54)-MIN($K$4:$K$54))+60*100*(L7-MIN($L$4:$L$54))/(MAX($L$4:$L$54)-MIN($L$4:$L$54))+10*100*(N7-MIN($N$4:$N$54))/(MAX($N$4:$N$54)-MIN($N$4:$N$54))+10*100*(O7-MIN($O$4:$O$54))/(MAX($O$4:$O$54)-MIN($O$4:$O$54)))/100,1)) -> 45.7 | R7: =IF(J7=0,"n/a",RANK(Q7,$Q$4:$Q$54)) -> 4
E8: IL | F8: 718 | G8: 241 | H8: 348 | I8: 81 | J8: 1 | K8: =IF(J8=0,"unstaffed",ROUND(F8/J8,0)) -> 718 | L8: =IF(J8=0,"unstaffed",ROUND(G8/J8,1)) -> 241 | M8: =H8/F8 -> 0.48467967 | N8: 1191812 | O8: 84033 | P8: 36.3 | Q8: =IF(J8=0,"unstaffed",ROUND((20*100*(K8-MIN($K$4:$K$54))/(MAX($K$4:$K$54)-MIN($K$4:$K$54))+60*100*(L8-MIN($L$4:$L$54))/(MAX($L$4:$L$54)-MIN($L$4:$L$54))+10*100*(N8-MIN($N$4:$N$54))/(MAX($N$4:$N$54)-MIN($N$4:$N$54))+10*100*(O8-MIN($O$4:$O$54))/(MAX($O$4:$O$54)-MIN($O$4:$O$54)))/100,1)) -> 38.8 | R8: =IF(J8=0,"n/a",RANK(Q8,$Q$4:$Q$54)) -> 5
E9: GA | F9: 683 | G9: 220 | H9: 122 | I9: 49 | J9: 1 | K9: =IF(J9=0,"unstaffed",ROUND(F9/J9,0)) -> 683 | L9: =IF(J9=0,"unstaffed",ROUND(G9/J9,1)) -> 220 | M9: =H9/F9 -> 0.17862372 | N9: 1070611 | O9: 75694 | P9: 33.4 | Q9: =IF(J9=0,"unstaffed",ROUND((20*100*(K9-MIN($K$4:$K$54))/(MAX($K$4:$K$54)-MIN($K$4:$K$54))+60*100*(L9-MIN($L$4:$L$54))/(MAX($L$4:$L$54)-MIN($L$4:$L$54))+10*100*(N9-MIN($N$4:$N$54))/(MAX($N$4:$N$54)-MIN($N$4:$N$54))+10*100*(O9-MIN($O$4:$O$54))/(MAX($O$4:$O$54)-MIN($O$4:$O$54)))/100,1)) -> 34.4 | R9: =IF(J9=0,"n/a",RANK(Q9,$Q$4:$Q$54)) -> 6
E10: MI | F10: 746 | G10: 207 | H10: 430 | I10: 95 | J10: 1 | K10: =IF(J10=0,"unstaffed",ROUND(F10/J10,0)) -> 746 | L10: =IF(J10=0,"unstaffed",ROUND(G10/J10,1)) -> 207 | M10: =H10/F10 -> 0.57640751 | N10: 910821 | O10: 72965 | P10: 31.3 | Q10: =IF(J10=0,"unstaffed",ROUND((20*100*(K10-MIN($K$4:$K$54))/(MAX($K$4:$K$54)-MIN($K$4:$K$54))+60*100*(L10-MIN($L$4:$L$54))/(MAX($L$4:$L$54)-MIN($L$4:$L$54))+10*100*(N10-MIN($N$4:$N$54))/(MAX($N$4:$N$54)-MIN($N$4:$N$54))+10*100*(O10-MIN($O$4:$O$54))/(MAX($O$4:$O$54)-MIN($O$4:$O$54)))/100,1)) -> 33 | R10: =IF(J10=0,"n/a",RANK(Q10,$Q$4:$Q$54)) -> 7
E11: NC | F11: 779 | G11: 181 | H11: 306 | I11: 71 | J11: 1 | K11: =IF(J11=0,"unstaffed",ROUND(F11/J11,0)) -> 779 | L11: =IF(J11=0,"unstaffed",ROUND(G11/J11,1)) -> 181 | M11: =H11/F11 -> 0.3928113 | N11: 975468 | O11: 70436 | P11: 34 | Q11: =IF(J11=0,"unstaffed",ROUND((20*100*(K11-MIN($K$4:$K$54))/(MAX($K$4:$K$54)-MIN($K$4:$K$54))+60*100*(L11-MIN($L$4:$L$54))/(MAX($L$4:$L$54)-MIN($L$4:$L$54))+10*100*(N11-MIN($N$4:$N$54))/(MAX($N$4:$N$54)-MIN($N$4:$N$54))+10*100*(O11-MIN($O$4:$O$54))/(MAX($O$4:$O$54)-MIN($O$4:$O$54)))/100,1)) -> 30.6 | R11: =IF(J11=0,"n/a",RANK(Q11,$Q$4:$Q$54)) -> 10
E12: OH | F12: 795 | G12: 178 | H12: 347 | I12: 74 | J12: 1 | K12: =IF(J12=0,"unstaffed",ROUND(F12/J12,0)) -> 795 | L12: =IF(J12=0,"unstaffed",ROUND(G12/J12,1)) -> 178 | M12: =H12/F12 -> 0.43647799 | N12: 1089150 | O12: 71229 | P12: 30.4 | Q12: =IF(J12=0,"unstaffed",ROUND((20*100*(K12-MIN($K$4:$K$54))/(MAX($K$4:$K$54)-MIN($K$4:$K$54))+60*100*(L12-MIN($L$4:$L$54))/(MAX($L$4:$L$54)-MIN($L$4:$L$54))+10*100*(N12-MIN($N$4:$N$54))/(MAX($N$4:$N$54)-MIN($N$4:$N$54))+10*100*(O12-MIN($O$4:$O$54))/(MAX($O$4:$O$54)-MIN($O$4:$O$54)))/100,1)) -> 31 | R12: =IF(J12=0,"n/a",RANK(Q12,$Q$4:$Q$54)) -> 9
E13: PA | F13: 607 | G13: 196 | H13: 237 | I13: 69 | J13: 1 | K13: =IF(J13=0,"unstaffed",ROUND(F13/J13,0)) -> 607 | L13: =IF(J13=0,"unstaffed",ROUND(G13/J13,1)) -> 196 | M13: =H13/F13 -> 0.39044481 | N13: 1145452 | O13: 78426 | P13: 33.7 | Q13: =IF(J13=0,"unstaffed",ROUND((20*100*(K13-MIN($K$4:$K$54))/(MAX($K$4:$K$54)-MIN($K$4:$K$54))+60*100*(L13-MIN($L$4:$L$54))/(MAX($L$4:$L$54)-MIN($L$4:$L$54))+10*100*(N13-MIN($N$4:$N$54))/(MAX($N$4:$N$54)-MIN($N$4:$N$54))+10*100*(O13-MIN($O$4:$O$54))/(MAX($O$4:$O$54)-MIN($O$4:$O$54)))/100,1)) -> 31.9 | R13: =IF(J13=0,"n/a",RANK(Q13,$Q$4:$Q$54)) -> 8
E14: VA | F14: 478 | G14: 137 | H14: 241 | I14: 49 | J14: 1 | K14: =IF(J14=0,"unstaffed",ROUND(F14/J14,0)) -> 478 | L14: =IF(J14=0,"unstaffed",ROUND(G14/J14,1)) -> 137 | M14: =H14/F14 -> 0.5041841 | N14: 794462 | O14: 97828 | P14: 41.1 | Q14: =IF(J14=0,"unstaffed",ROUND((20*100*(K14-MIN($K$4:$K$54))/(MAX($K$4:$K$54)-MIN($K$4:$K$54))+60*100*(L14-MIN($L$4:$L$54))/(MAX($L$4:$L$54)-MIN($L$4:$L$54))+10*100*(N14-MIN($N$4:$N$54))/(MAX($N$4:$N$54)-MIN($N$4:$N$54))+10*100*(O14-MIN($O$4:$O$54))/(MAX($O$4:$O$54)-MIN($O$4:$O$54)))/100,1)) -> 27.6 | R14: =IF(J14=0,"n/a",RANK(Q14,$Q$4:$Q$54)) -> 12
E15: NJ | F15: 428 | G15: 142 | H15: 195 | I15: 44 | J15: 1 | K15: =IF(J15=0,"unstaffed",ROUND(F15/J15,0)) -> 428 | L15: =IF(J15=0,"unstaffed",ROUND(G15/J15,1)) -> 142 | M15: =H15/F15 -> 0.45560748 | N15: 839980 | O15: 105301 | P15: 41.9 | Q15: =IF(J15=0,"unstaffed",ROUND((20*100*(K15-MIN($K$4:$K$54))/(MAX($K$4:$K$54)-MIN($K$4:$K$54))+60*100*(L15-MIN($L$4:$L$54))/(MAX($L$4:$L$54)-MIN($L$4:$L$54))+10*100*(N15-MIN($N$4:$N$54))/(MAX($N$4:$N$54)-MIN($N$4:$N$54))+10*100*(O15-MIN($O$4:$O$54))/(MAX($O$4:$O$54)-MIN($O$4:$O$54)))/100,1)) -> 29.1 | R15: =IF(J15=0,"n/a",RANK(Q15,$Q$4:$Q$54)) -> 11
... E54: DE | F54: 28 | G54: 14 | H54: 3 | I54: 2 | J54: 1 | K54: =IF(J54=0,"unstaffed",ROUND(F54/J54,0)) -> 28 | L54: =IF(J54=0,"unstaffed",ROUND(G54/J54,1)) -> 14 | M54: =H54/F54 -> 0.10714286 | N54: 88852 | O54: 82098 | P54: 33.8 | Q54: =IF(J54=0,"unstaffed",ROUND((20*100*(K54-MIN($K$4:$K$54))/(MAX($K$4:$K$54)-MIN($K$4:$K$54))+60*100*(L54-MIN($L$4:$L$54))/(MAX($L$4:$L$54)-MIN($L$4:$L$54))+10*100*(N54-MIN($N$4:$N$54))/(MAX($N$4:$N$54)-MIN($N$4:$N$54))+10*100*(O54-MIN($O$4:$O$54))/(MAX($O$4:$O$54)-MIN($O$4:$O$54)))/100,1)) -> 5.4 | R54: =IF(J54=0,"n/a",RANK(Q54,$Q$4:$Q$54)) -> 44
E55: TOTAL | F55: =SUM(F4:F54) -> 18405 | G55: =SUM(G4:G54) -> 5862 | H55: =SUM(H4:H54) -> 7524 | I55: =SUM(I4:I54) -> 2208 | J55: =SUM(J4:J54) -> 51 | K55: =ROUND(F55/J55,0) -> 361 | L55: =ROUND(G55/J55,1) -> 114.9 | M55: =H55/F55 -> 0.40880196 | N55: =SUM(N4:N54) -> 30870179
E57: Note: Reps defaults to 1/state (sum 51) as a neutral ranking baseline — NOT the staffing plan (the 30-rep allocation lives on Territory Plan / Kathy - ALL Universe). As you group states into territories, set Reps here or send the groupings over and the territory tabs will be rewired.

Sheet Territory Plan
A1: Territory | B1: States | C1: Anchor Markets | D1: All MDs | E1: All Clinics | F1: Reps (28 cap, v3 allocation — ADJUSTABLE) | G1: MDs per Rep | H1: Clinics per Rep | I1: Women 25-44 (v3) | J1: Wtd Income (v3) | K1: Score v7 | L1: Rank v7 | M1: Rank v3 | N1: Rank Change | O1: Hire Wave (Kathy weights)
A2: T01 | B2: TX | C2: Houston, Dallas, Austin | D2: =SUMIF('State Market Summary'!$T$4:$T$54,$A2,'State Market Summary'!$B$4:$B$54) -> 1660 | E2: =SUMIF('State Market Summary'!$T$4:$T$54,$A2,'State Market Summary'!$C$4:$C$54) -> 540 | F2: 2 | G2: =IF(F2=0,"unstaffed",ROUND(D2/F2,0)) -> 830 | H2: =IF(F2=0,"unstaffed",ROUND(E2/F2,1)) -> 270 | I2: 3090173 | J2: 78473 | K2: =ROUND((40*D2/MAX($D$2:$D$26)+25*E2/MAX($E$2:$E$26)+10*I2/MAX($I$2:$I$26)+10*J2/MAX($J$2:$J$26))/85*100,1) -> 89.1 | L2: =RANK(K2,$K$2:$K$26) -> 2 | M2: 1 | N2: =M2-L2 -> -1 | O2: ='Kathy - ALL Universe'!S4 -> 1
A3: T02 | B3: CA-HI | C3: Sacramento, Los Angeles, San Diego | D3: =SUMIF('State Market Summary'!$T$4:$T$54,$A3,'State Market Summary'!$B$4:$B$54) -> 1579 | E3: =SUMIF('State Market Summary'!$T$4:$T$54,$A3,'State Market Summary'!$C$4:$C$54) -> 688 | F3: 2 | G3: =IF(F3=0,"unstaffed",ROUND(D3/F3,0)) -> 790 | H3: =IF(F3=0,"unstaffed",ROUND(E3/F3,1)) -> 344 | I3: 3819366 | J3: 97969 | K3: =ROUND((40*D3/MAX($D$2:$D$26)+25*E3/MAX($E$2:$E$26)+10*I3/MAX($I$2:$I$26)+10*J3/MAX($J$2:$J$26))/85*100,1) -> 97.7 | L3: =RANK(K3,$K$2:$K$26) -> 1 | M3: 2 | N3: =M3-L3 -> 1 | O3: ='Kathy - ALL Universe'!S5 -> 1
A4: T03 | B4: NY | C4: New York, Brooklyn, Bronx | D4: =SUMIF('State Market Summary'!$T$4:$T$54,$A4,'State Market Summary'!$B$4:$B$54) -> 1030 | E4: =SUMIF('State Market Summary'!$T$4:$T$54,$A4,'State Market Summary'!$C$4:$C$54) -> 404 | F4: 2 | G4: =IF(F4=0,"unstaffed",ROUND(D4/F4,0)) -> 515 | H4: =IF(F4=0,"unstaffed",ROUND(E4/F4,1)) -> 202 | I4: 1726412 | J4: 89542 | K4: =ROUND((40*D4/MAX($D$2:$D$26)+25*E4/MAX($E$2:$E$26)+10*I4/MAX($I$2:$I$26)+10*J4/MAX($J$2:$J$26))/85*100,1) -> 62.5 | L4: =RANK(K4,$K$2:$K$26) -> 3 | M4: 3 | N4: =M4-L4 -> 0 | O4: ='Kathy - ALL Universe'!S6 -> 2
A5: T04 | B5: OH | C5: Columbus, Cincinnati, Cleveland | D5: =SUMIF('State Market Summary'!$T$4:$T$54,$A5,'State Market Summary'!$B$4:$B$54) -> 795 | E5: =SUMIF('State Market Summary'!$T$4:$T$54,$A5,'State Market Summary'!$C$4:$C$54) -> 178 | F5: 1 | G5: =IF(F5=0,"unstaffed",ROUND(D5/F5,0)) -> 795 | H5: =IF(F5=0,"unstaffed",ROUND(E5/F5,1)) -> 178 | I5: 1089150 | J5: 71229 | K5: =ROUND((40*D5/MAX($D$2:$D$26)+25*E5/MAX($E$2:$E$26)+10*I5/MAX($I$2:$I$26)+10*J5/MAX($J$2:$J$26))/85*100,1) -> 42.1 | L5: =RANK(K5,$K$2:$K$26) -> 10 | M5: 4 | N5: =M5-L5 -> -6 | O5: ='Kathy - ALL Universe'!S7 -> 2
A6: T05 | B6: FL | C6: Miami, Boca Raton, Tampa | D6: =SUMIF('State Market Summary'!$T$4:$T$54,$A6,'State Market Summary'!$B$4:$B$54) -> 1107 | E6: =SUMIF('State Market Summary'!$T$4:$T$54,$A6,'State Market Summary'!$C$4:$C$54) -> 273 | F6: 2 | G6: =IF(F6=0,"unstaffed",ROUND(D6/F6,0)) -> 554 | H6: =IF(F6=0,"unstaffed",ROUND(E6/F6,1)) -> 136.5 | I6: 1780020 | J6: 71602 | K6: =ROUND((40*D6/MAX($D$2:$D$26)+25*E6/MAX($E$2:$E$26)+10*I6/MAX($I$2:$I$26)+10*J6/MAX($J$2:$J$26))/85*100,1) -> 57.1 | L6: =RANK(K6,$K$2:$K$26) -> 5 | M6: 5 | N6: =M6-L6 -> 0 | O6: ='Kathy - ALL Universe'!S8 -> 4
A7: T06 | B7: PA-NJ | C7: Pittsburgh, Philadelphia, Voorhees | D7: =SUMIF('State Market Summary'!$T$4:$T$54,$A7,'State Market Summary'!$B$4:$B$54) -> 1035 | E7: =SUMIF('State Market Summary'!$T$4:$T$54,$A7,'State Market Summary'!$C$4:$C$54) -> 338 | F7: 2 | G7: =IF(F7=0,"unstaffed",ROUND(D7/F7,0)) -> 518 | H7: =IF(F7=0,"unstaffed",ROUND(E7/F7,1)) -> 169 | I7: 1985432 | J7: 89604 | K7: =ROUND((40*D7/MAX($D$2:$D$26)+25*E7/MAX($E$2:$E$26)+10*I7/MAX($I$2:$I$26)+10*J7/MAX($J$2:$J$26))/85*100,1) -> 60.7 | L7: =RANK(K7,$K$2:$K$26) -> 4 | M7: 6 | N7: =M7-L7 -> 2 | O7: ='Kathy - ALL Universe'!S9 -> 3
A8: T07 | B8: MI | C8: Royal Oak, Rochester, Ann Arbor | D8: =SUMIF('State Market Summary'!$T$4:$T$54,$A8,'State Market Summary'!$B$4:$B$54) -> 746 | E8: =SUMIF('State Market Summary'!$T$4:$T$54,$A8,'State Market Summary'!$C$4:$C$54) -> 207 | F8: 1 | G8: =IF(F8=0,"unstaffed",ROUND(D8/F8,0)) -> 746 | H8: =IF(F8=0,"unstaffed",ROUND(E8/F8,1)) -> 207 | I8: 910821 | J8: 72965 | K8: =ROUND((40*D8/MAX($D$2:$D$26)+25*E8/MAX($E$2:$E$26)+10*I8/MAX($I$2:$I$26)+10*J8/MAX($J$2:$J$26))/85*100,1) -> 41.6 | L8: =RANK(K8,$K$2:$K$26) -> 11 | M8: 7 | N8: =M8-L8 -> -4 | O8: ='Kathy - ALL Universe'!S10 -> 2
A9: T08 | B9: MA-CT-NH-ME-VT-RI | C9: Boston, Rocky Hill, Scarborough | D9: =SUMIF('State Market Summary'!$T$4:$T$54,$A9,'State Market Summary'!$B$4:$B$54) -> 918 | E9: =SUMIF('State Market Summary'!$T$4:$T$54,$A9,'State Market Summary'!$C$4:$C$54) -> 279 | F9: 1 | G9: =IF(F9=0,"unstaffed",ROUND(D9/F9,0)) -> 918 | H9: =IF(F9=0,"unstaffed",ROUND(E9/F9,1)) -> 279 | I9: 1294309 | J9: 97019 | K9: =ROUND((40*D9/MAX($D$2:$D$26)+25*E9/MAX($E$2:$E$26)+10*I9/MAX($I$2:$I$26)+10*J9/MAX($J$2:$J$26))/85*100,1) -> 53.6 | L9: =RANK(K9,$K$2:$K$26) -> 6 | M9: 8 | N9: =M9-L9 -> 2 | O9: ='Kathy - ALL Universe'!S11 -> 1
A10: T09 | B10: MN-WI | C10: Minneapolis, Milwaukee, Saint Paul | D10: =SUMIF('State Market Summary'!$T$4:$T$54,$A10,'State Market Summary'!$B$4:$B$54) -> 758 | E10: =SUMIF('State Market Summary'!$T$4:$T$54,$A10,'State Market Summary'!$C$4:$C$54) -> 176 | F10: 1 | G10: =IF(F10=0,"unstaffed",ROUND(D10/F10,0)) -> 758 | H10: =IF(F10=0,"unstaffed",ROUND(E10/F10,1)) -> 176 | I10: 1084210 | J10: 81797 | K10: =ROUND((40*D10/MAX($D$2:$D$26)+25*E10/MAX($E$2:$E$26)+10*I10/MAX($I$2:$I$26)+10*J10/MAX($J$2:$J$26))/85*100,1) -> 42.2 | L10: =RANK(K10,$K$2:$K$26) -> 9 | M10: 9 | N10: =M10-L10 -> 0 | O10: ='Kathy - ALL Universe'!S12 -> 2
A11: T10 | B11: MO-KY | C11: Saint Louis, Lexington, Bowling Green | D11: =SUMIF('State Market Summary'!$T$4:$T$54,$A11,'State Market Summary'!$B$4:$B$54) -> 664 | E11: =SUMIF('State Market Summary'!$T$4:$T$54,$A11,'State Market Summary'!$C$4:$C$54) -> 200 | F11: 1 | G11: =IF(F11=0,"unstaffed",ROUND(D11/F11,0)) -> 664 | H11: =IF(F11=0,"unstaffed",ROUND(E11/F11,1)) -> 200 | I11: 995376 | J11: 67472 | K11: =ROUND((40*D11/MAX($D$2:$D$26)+25*E11/MAX($E$2:$E$26)+10*I11/MAX($I$2:$I$26)+10*J11/MAX($J$2:$J$26))/85*100,1) -> 38.5 | L11: =RANK(K11,$K$2:$K$26) -> 15 | M11: 10 | N11: =M11-L11 -> -5 | O11: ='Kathy - ALL Universe'!S13 -> 3
A12: T11 | B12: GA | C12: Atlanta, Augusta, Gainesville | D12: =SUMIF('State Market Summary'!$T$4:$T$54,$A12,'State Market Summary'!$B$4:$B$54) -> 683 | E12: =SUMIF('State Market Summary'!$T$4:$T$54,$A12,'State Market Summary'!$C$4:$C$54) -> 220 | F12: 1 | G12: =IF(F12=0,"unstaffed",ROUND(D12/F12,0)) -> 683 | H12: =IF(F12=0,"unstaffed",ROUND(E12/F12,1)) -> 220 | I12: 1070611 | J12: 75694 | K12: =ROUND((40*D12/MAX($D$2:$D$26)+25*E12/MAX($E$2:$E$26)+10*I12/MAX($I$2:$I$26)+10*J12/MAX($J$2:$J$26))/85*100,1) -> 41.2 | L12: =RANK(K12,$K$2:$K$26) -> 13 | M12: 11 | N12: =M12-L12 -> -2 | O12: ='Kathy - ALL Universe'!S14 -> 1
A13: T12 | B13: WA-OR-AK | C13: Portland, Seattle, Anchorage | D13: =SUMIF('State Market Summary'!$T$4:$T$54,$A13,'State Market Summary'!$B$4:$B$54) -> 734 | E13: =SUMIF('State Market Summary'!$T$4:$T$54,$A13,'State Market Summary'!$C$4:$C$54) -> 225 | F13: 1 | G13: =IF(F13=0,"unstaffed",ROUND(D13/F13,0)) -> 734 | H13: =IF(F13=0,"unstaffed",ROUND(E13/F13,1)) -> 225 | I13: 1119028 | J13: 90198 | K13: =ROUND((40*D13/MAX($D$2:$D$26)+25*E13/MAX($E$2:$E$26)+10*I13/MAX($I$2:$I$26)+10*J13/MAX($J$2:$J$26))/85*100,1) -> 44.7 | L13: =RANK(K13,$K$2:$K$26) -> 7 | M13: 12 | N13: =M13-L13 -> 5 | O13: ='Kathy - ALL Universe'!S15 -> 1
... A26: T25 | B26: SC | C26: Greenville, Florence, Spartanburg | D26: =SUMIF('State Market Summary'!$T$4:$T$54,$A26,'State Market Summary'!$B$4:$B$54) -> 364 | E26: =SUMIF('State Market Summary'!$T$4:$T$54,$A26,'State Market Summary'!$C$4:$C$54) -> 97 | F26: 1 | G26: =IF(F26=0,"unstaffed",ROUND(D26/F26,0)) -> 364 | H26: =IF(F26=0,"unstaffed",ROUND(E26/F26,1)) -> 97 | I26: 473826 | J26: 65973 | K26: =ROUND((40*D26/MAX($D$2:$D$26)+25*E26/MAX($E$2:$E$26)+10*I26/MAX($I$2:$I$26)+10*J26/MAX($J$2:$J$26))/85*100,1) -> 23.8 | L26: =RANK(K26,$K$2:$K$26) -> 25 | M26: 25 | N26: =M26-L26 -> 0 | O26: ='Kathy - ALL Universe'!S28 -> 4
A27: TOTAL | D27: =SUM(D2:D26) -> 18405 | E27: =SUM(E2:E26) -> 5862 | F27: =SUM(F2:F26) -> 30 | G27: =ROUND(D27/F27,0) -> 614 | H27: =ROUND(E27/F27,1) -> 195.4 | I27: =SUM(I2:I26) -> 30870179
A29: HARD CAP: 30 reps. Allocation (blue, adjustable — keep the column total at 30): 2 reps each for TX, CA-HI, NY, FL, PA-NJ; 1 rep for all other 20 territories. Per-rep loads and dependent figures recalculate. PRIORITIZATION: hiring waves are driven by the Kathy - ALL Universe score/rank (per-rep weights 20/60/10/10); the Score v7 column here (market-size weights, rep-independent) is retained for reference only. Against the ALL-MD universe (18,405) the 30 reps average ~614 MDs each — use with the >=10 / >=20 tiers on State Market Summary as a prioritization model. Women 25-44 and Wtd Income carried from v3 unchanged (blue = input).

Sheet Hiring Waves
A1: Wave | B1: Territories Staffed (v7 score order) | C1: Reps Added | D1: Cumulative Reps | E1: Rationale
A2: Wave 1 | B2: T02 CA-HI; T08 MA-CT-NH-ME-VT-RI; T01 TX; T17 IL; T12 WA-OR-AK; T11 GA; T15 AZ-NV-ID-MT | C2: =SUMIF('Kathy - ALL Universe'!$S$4:$S$28,1,'Kathy - ALL Universe'!$J$4:$J$28) -> 9 | D2: =SUM($C$2:$C2) -> 9 | E2: Highest Kathy-weighted score; staff first
A3: Wave 2 | B3: T07 MI; T03 NY; T09 MN-WI; T04 OH; T13 NC | C3: =SUMIF('Kathy - ALL Universe'!$S$4:$S$28,2,'Kathy - ALL Universe'!$J$4:$J$28) -> 6 | D3: =SUM($C$2:$C3) -> 15 | E3: Second tier
A4: Wave 3 | B4: T10 MO-KY; T16 CO-UT; T14 KS-OK-NE-NM; T06 PA-NJ; T22 MD-WV-DE-DC; T21 VA; T19 LA-AR | C4: =SUMIF('Kathy - ALL Universe'!$S$4:$S$28,3,'Kathy - ALL Universe'!$J$4:$J$28) -> 8 | D4: =SUM($C$2:$C4) -> 23 | E4: Regional completion
A5: Wave 4 | B5: T05 FL; T18 AL-MS; T23 TN; T20 IN; T24 IA-SD-ND-WY; T25 SC | C5: =SUMIF('Kathy - ALL Universe'!$S$4:$S$28,4,'Kathy - ALL Universe'!$J$4:$J$28) -> 7 | D5: =SUM($C$2:$C5) -> 30 | E5: Balance of the 28; includes the two unstaffed territories
A7: CAVEAT: rankings are pure opportunity, not mandate-adjusted. Northeast (incl. mandate states) remains in early waves under v3 weights. Verify the current mandate list (Phase 2) and re-sequence before committing hires.
A8: v7 notes: waves ranked by the Kathy - ALL Universe score (All MDs/Rep 20% / All Clinics/Rep 60% / Women 25-44 10% / Median Income 10%), wave sizes 7/5/7/6. Rep counts use the hard 30-cap allocation (2 each: TX, CA-HI, NY, FL, PA-NJ; 1 each: 18 territories). Cumulative total = 30. NOTE: because the score weights per-rep load, editing the Reps column re-shuffles ranks and wave membership; the wave lists in column B are a snapshot of the current allocation — re-check after any rep change.

Sheet Kathy - ALL Universe
E1: Kathy - ALL Universe: all counts sum Waterfall A rev1 labeled columns with MSO reclassification (via State Market Summary; see MSO Reclassification tab). Reps (J, blue) = the 30-rep hard-cap allocation (2 each: TX, CA-HI, NY, FL, PA-NJ; 1 each: all other 20 territories) — overwrite freely, keep total 30; per-rep loads, Academic Share, Score, and Rank recalculate. All territories are staffed.
J2: Weights: | K2: 20% | L2: 60% | N2: 10% | O2: 10% | P2: 0%
E3: Territory | F3: All MDs | G3: All Clinics | H3: All Academic/Group MDs | I3: All Academic/Group Clinics | J3: Reps | K3: All MDs/Rep | L3: All Clinics/Rep | M3: Academic Share | N3: Women 25-44 | O3: Median Income | P3: Education | Q3: Score | R3: Rank | S3: Hire Wave
E4: T01 TX | F4: =SUMIF('State Market Summary'!$T$4:$T$54,"T01",'State Market Summary'!$B$4:$B$54) -> 1660 | G4: =SUMIF('State Market Summary'!$T$4:$T$54,"T01",'State Market Summary'!$C$4:$C$54) -> 540 | H4: =SUMIF('State Market Summary'!$T$4:$T$54,"T01",'State Market Summary'!$N$4:$N$54) -> 546 | I4: =SUMIF('State Market Summary'!$T$4:$T$54,"T01",'State Market Summary'!$O$4:$O$54) -> 126 | J4: 2 | K4: =IF(J4=0,"unstaffed",ROUND(F4/J4,0)) -> 830 | L4: =IF(J4=0,"unstaffed",ROUND(G4/J4,1)) -> 270 | M4: =H4/F4 -> 0.32891566 | N4: 3090173 | O4: 78473 | P4: 31.7 | Q4: =IF(J4=0,"unstaffed",ROUND((20*100*(K4-MIN($K$4:$K$28))/(MAX($K$4:$K$28)-MIN($K$4:$K$28))+60*100*(L4-MIN($L$4:$L$28))/(MAX($L$4:$L$28)-MIN($L$4:$L$28))+10*100*(N4-MIN($N$4:$N$28))/(MAX($N$4:$N$28)-MIN($N$4:$N$28))+10*100*(O4-MIN($O$4:$O$28))/(MAX($O$4:$O$28)-MIN($O$4:$O$28)))/100,1)) -> 71.7 | R4: =IF(J4=0,"n/a",RANK(Q4,$Q$4:$Q$28)) -> 3 | S4: =IF(J4=0,4,IF(R4<=7,1,IF(R4<=12,2,IF(R4<=19,3,4)))) -> 1
E5: T02 CA-HI | F5: =SUMIF('State Market Summary'!$T$4:$T$54,"T02",'State Market Summary'!$B$4:$B$54) -> 1579 | G5: =SUMIF('State Market Summary'!$T$4:$T$54,"T02",'State Market Summary'!$C$4:$C$54) -> 688 | H5: =SUMIF('State Market Summary'!$T$4:$T$54,"T02",'State Market Summary'!$N$4:$N$54) -> 857 | I5: =SUMIF('State Market Summary'!$T$4:$T$54,"T02",'State Market Summary'!$O$4:$O$54) -> 267 | J5: 2 | K5: =IF(J5=0,"unstaffed",ROUND(F5/J5,0)) -> 790 | L5: =IF(J5=0,"unstaffed",ROUND(G5/J5,1)) -> 344 | M5: =H5/F5 -> 0.54274858 | N5: 3819366 | O5: 97969 | P5: 34.9 | Q5: =IF(J5=0,"unstaffed",ROUND((20*100*(K5-MIN($K$4:$K$28))/(MAX($K$4:$K$28)-MIN($K$4:$K$28))+60*100*(L5-MIN($L$4:$L$28))/(MAX($L$4:$L$28)-MIN($L$4:$L$28))+10*100*(N5-MIN($N$4:$N$28))/(MAX($N$4:$N$28)-MIN($N$4:$N$28))+10*100*(O5-MIN($O$4:$O$28))/(MAX($O$4:$O$28)-MIN($O$4:$O$28)))/100,1)) -> 95.5 | R5: =IF(J5=0,"n/a",RANK(Q5,$Q$4:$Q$28)) -> 1 | S5: =IF(J5=0,4,IF(R5<=7,1,IF(R5<=12,2,IF(R5<=19,3,4)))) -> 1
E6: T03 NY | F6: =SUMIF('State Market Summary'!$T$4:$T$54,"T03",'State Market Summary'!$B$4:$B$54) -> 1030 | G6: =SUMIF('State Market Summary'!$T$4:$T$54,"T03",'State Market Summary'!$C$4:$C$54) -> 404 | H6: =SUMIF('State Market Summary'!$T$4:$T$54,"T03",'State Market Summary'!$N$4:$N$54) -> 413 | I6: =SUMIF('State Market Summary'!$T$4:$T$54,"T03",'State Market Summary'!$O$4:$O$54) -> 148 | J6: 2 | K6: =IF(J6=0,"unstaffed",ROUND(F6/J6,0)) -> 515 | L6: =IF(J6=0,"unstaffed",ROUND(G6/J6,1)) -> 202 | M6: =H6/F6 -> 0.40097087 | N6: 1726412 | O6: 89542 | P6: 38.3 | Q6: =IF(J6=0,"unstaffed",ROUND((20*100*(K6-MIN($K$4:$K$28))/(MAX($K$4:$K$28)-MIN($K$4:$K$28))+60*100*(L6-MIN($L$4:$L$28))/(MAX($L$4:$L$28)-MIN($L$4:$L$28))+10*100*(N6-MIN($N$4:$N$28))/(MAX($N$4:$N$28)-MIN($N$4:$N$28))+10*100*(O6-MIN($O$4:$O$28))/(MAX($O$4:$O$28)-MIN($O$4:$O$28)))/100,1)) -> 43 | R6: =IF(J6=0,"n/a",RANK(Q6,$Q$4:$Q$28)) -> 9 | S6: =IF(J6=0,4,IF(R6<=7,1,IF(R6<=12,2,IF(R6<=19,3,4)))) -> 2
E7: T04 OH | F7: =SUMIF('State Market Summary'!$T$4:$T$54,"T04",'State Market Summary'!$B$4:$B$54) -> 795 | G7: =SUMIF('State Market Summary'!$T$4:$T$54,"T04",'State Market Summary'!$C$4:$C$54) -> 178 | H7: =SUMIF('State Market Summary'!$T$4:$T$54,"T04",'State Market Summary'!$N$4:$N$54) -> 347 | I7: =SUMIF('State Market Summary'!$T$4:$T$54,"T04",'State Market Summary'!$O$4:$O$54) -> 74 | J7: 1 | K7: =IF(J7=0,"unstaffed",ROUND(F7/J7,0)) -> 795 | L7: =IF(J7=0,"unstaffed",ROUND(G7/J7,1)) -> 178 | M7: =H7/F7 -> 0.43647799 | N7: 1089150 | O7: 71229 | P7: 30.4 | Q7: =IF(J7=0,"unstaffed",ROUND((20*100*(K7-MIN($K$4:$K$28))/(MAX($K$4:$K$28)-MIN($K$4:$K$28))+60*100*(L7-MIN($L$4:$L$28))/(MAX($L$4:$L$28)-MIN($L$4:$L$28))+10*100*(N7-MIN($N$4:$N$28))/(MAX($N$4:$N$28)-MIN($N$4:$N$28))+10*100*(O7-MIN($O$4:$O$28))/(MAX($O$4:$O$28)-MIN($O$4:$O$28)))/100,1)) -> 40.2 | R7: =IF(J7=0,"n/a",RANK(Q7,$Q$4:$Q$28)) -> 11 | S7: =IF(J7=0,4,IF(R7<=7,1,IF(R7<=12,2,IF(R7<=19,3,4)))) -> 2
E8: T05 FL | F8: =SUMIF('State Market Summary'!$T$4:$T$54,"T05",'State Market Summary'!$B$4:$B$54) -> 1107 | G8: =SUMIF('State Market Summary'!$T$4:$T$54,"T05",'State Market Summary'!$C$4:$C$54) -> 273 | H8: =SUMIF('State Market Summary'!$T$4:$T$54,"T05",'State Market Summary'!$N$4:$N$54) -> 278 | I8: =SUMIF('State Market Summary'!$T$4:$T$54,"T05",'State Market Summary'!$O$4:$O$54) -> 120 | J8: 2 | K8: =IF(J8=0,"unstaffed",ROUND(F8/J8,0)) -> 554 | L8: =IF(J8=0,"unstaffed",ROUND(G8/J8,1)) -> 136.5 | M8: =H8/F8 -> 0.25112918 | N8: 1780020 | O8: 71602 | P8: 32.2 | Q8: =IF(J8=0,"unstaffed",ROUND((20*100*(K8-MIN($K$4:$K$28))/(MAX($K$4:$K$28)-MIN($K$4:$K$28))+60*100*(L8-MIN($L$4:$L$28))/(MAX($L$4:$L$28)-MIN($L$4:$L$28))+10*100*(N8-MIN($N$4:$N$28))/(MAX($N$4:$N$28)-MIN($N$4:$N$28))+10*100*(O8-MIN($O$4:$O$28))/(MAX($O$4:$O$28)-MIN($O$4:$O$28)))/100,1)) -> 23.9 | R8: =IF(J8=0,"n/a",RANK(Q8,$Q$4:$Q$28)) -> 20 | S8: =IF(J8=0,4,IF(R8<=7,1,IF(R8<=12,2,IF(R8<=19,3,4)))) -> 4
E9: T06 PA-NJ | F9: =SUMIF('State Market Summary'!$T$4:$T$54,"T06",'State Market Summary'!$B$4:$B$54) -> 1035 | G9: =SUMIF('State Market Summary'!$T$4:$T$54,"T06",'State Market Summary'!$C$4:$C$54) -> 338 | H9: =SUMIF('State Market Summary'!$T$4:$T$54,"T06",'State Market Summary'!$N$4:$N$54) -> 432 | I9: =SUMIF('State Market Summary'!$T$4:$T$54,"T06",'State Market Summary'!$O$4:$O$54) -> 113 | J9: 2 | K9: =IF(J9=0,"unstaffed",ROUND(F9/J9,0)) -> 518 | L9: =IF(J9=0,"unstaffed",ROUND(G9/J9,1)) -> 169 | M9: =H9/F9 -> 0.4173913 | N9: 1985432 | O9: 89604 | P9: 37.1 | Q9: =IF(J9=0,"unstaffed",ROUND((20*100*(K9-MIN($K$4:$K$28))/(MAX($K$4:$K$28)-MIN($K$4:$K$28))+60*100*(L9-MIN($L$4:$L$28))/(MAX($L$4:$L$28)-MIN($L$4:$L$28))+10*100*(N9-MIN($N$4:$N$28))/(MAX($N$4:$N$28)-MIN($N$4:$N$28))+10*100*(O9-MIN($O$4:$O$28))/(MAX($O$4:$O$28)-MIN($O$4:$O$28)))/100,1)) -> 35.9 | R9: =IF(J9=0,"n/a",RANK(Q9,$Q$4:$Q$28)) -> 16 | S9: =IF(J9=0,4,IF(R9<=7,1,IF(R9<=12,2,IF(R9<=19,3,4)))) -> 3
E10: T07 MI | F10: =SUMIF('State Market Summary'!$T$4:$T$54,"T07",'State Market Summary'!$B$4:$B$54) -> 746 | G10: =SUMIF('State Market Summary'!$T$4:$T$54,"T07",'State Market Summary'!$C$4:$C$54) -> 207 | H10: =SUMIF('State Market Summary'!$T$4:$T$54,"T07",'State Market Summary'!$N$4:$N$54) -> 430 | I10: =SUMIF('State Market Summary'!$T$4:$T$54,"T07",'State Market Summary'!$O$4:$O$54) -> 95 | J10: 1 | K10: =IF(J10=0,"unstaffed",ROUND(F10/J10,0)) -> 746 | L10: =IF(J10=0,"unstaffed",ROUND(G10/J10,1)) -> 207 | M10: =H10/F10 -> 0.57640751 | N10: 910821 | O10: 72965 | P10: 31.3 | Q10: =IF(J10=0,"unstaffed",ROUND((20*100*(K10-MIN($K$4:$K$28))/(MAX($K$4:$K$28)-MIN($K$4:$K$28))+60*100*(L10-MIN($L$4:$L$28))/(MAX($L$4:$L$28)-MIN($L$4:$L$28))+10*100*(N10-MIN($N$4:$N$28))/(MAX($N$4:$N$28)-MIN($N$4:$N$28))+10*100*(O10-MIN($O$4:$O$28))/(MAX($O$4:$O$28)-MIN($O$4:$O$28)))/100,1)) -> 45.5 | R10: =IF(J10=0,"n/a",RANK(Q10,$Q$4:$Q$28)) -> 8 | S10: =IF(J10=0,4,IF(R10<=7,1,IF(R10<=12,2,IF(R10<=19,3,4)))) -> 2
E11: T08 MA-CT-NH-ME-VT-RI | F11: =SUMIF('State Market Summary'!$T$4:$T$54,"T08",'State Market Summary'!$B$4:$B$54) -> 918 | G11: =SUMIF('State Market Summary'!$T$4:$T$54,"T08",'State Market Summary'!$C$4:$C$54) -> 279 | H11: =SUMIF('State Market Summary'!$T$4:$T$54,"T08",'State Market Summary'!$N$4:$N$54) -> 430 | I11: =SUMIF('State Market Summary'!$T$4:$T$54,"T08",'State Market Summary'!$O$4:$O$54) -> 135 | J11: 1 | K11: =IF(J11=0,"unstaffed",ROUND(F11/J11,0)) -> 918 | L11: =IF(J11=0,"unstaffed",ROUND(G11/J11,1)) -> 279 | M11: =H11/F11 -> 0.46840959 | N11: 1294309 | O11: 97019 | P11: 42.3 | Q11: =IF(J11=0,"unstaffed",ROUND((20*100*(K11-MIN($K$4:$K$28))/(MAX($K$4:$K$28)-MIN($K$4:$K$28))+60*100*(L11-MIN($L$4:$L$28))/(MAX($L$4:$L$28)-MIN($L$4:$L$28))+10*100*(N11-MIN($N$4:$N$28))/(MAX($N$4:$N$28)-MIN($N$4:$N$28))+10*100*(O11-MIN($O$4:$O$28))/(MAX($O$4:$O$28)-MIN($O$4:$O$28)))/100,1)) -> 76.4 | R11: =IF(J11=0,"n/a",RANK(Q11,$Q$4:$Q$28)) -> 2 | S11: =IF(J11=0,4,IF(R11<=7,1,IF(R11<=12,2,IF(R11<=19,3,4)))) -> 1
E12: T09 MN-WI | F12: =SUMIF('State Market Summary'!$T$4:$T$54,"T09",'State Market Summary'!$B$4:$B$54) -> 758 | G12: =SUMIF('State Market Summary'!$T$4:$T$54,"T09",'State Market Summary'!$C$4:$C$54) -> 176 | H12: =SUMIF('State Market Summary'!$T$4:$T$54,"T09",'State Market Summary'!$N$4:$N$54) -> 373 | I12: =SUMIF('State Market Summary'!$T$4:$T$54,"T09",'State Market Summary'!$O$4:$O$54) -> 87 | J12: 1 | K12: =IF(J12=0,"unstaffed",ROUND(F12/J12,0)) -> 758 | L12: =IF(J12=0,"unstaffed",ROUND(G12/J12,1)) -> 176 | M12: =H12/F12 -> 0.49208443 | N12: 1084210 | O12: 81797 | P12: 35.1 | Q12: =IF(J12=0,"unstaffed",ROUND((20*100*(K12-MIN($K$4:$K$28))/(MAX($K$4:$K$28)-MIN($K$4:$K$28))+60*100*(L12-MIN($L$4:$L$28))/(MAX($L$4:$L$28)-MIN($L$4:$L$28))+10*100*(N12-MIN($N$4:$N$28))/(MAX($N$4:$N$28)-MIN($N$4:$N$28))+10*100*(O12-MIN($O$4:$O$28))/(MAX($O$4:$O$28)-MIN($O$4:$O$28)))/100,1)) -> 41.2 | R12: =IF(J12=0,"n/a",RANK(Q12,$Q$4:$Q$28)) -> 10 | S12: =IF(J12=0,4,IF(R12<=7,1,IF(R12<=12,2,IF(R12<=19,3,4)))) -> 2
E13: T10 MO-KY | F13: =SUMIF('State Market Summary'!$T$4:$T$54,"T10",'State Market Summary'!$B$4:$B$54) -> 664 | G13: =SUMIF('State Market Summary'!$T$4:$T$54,"T10",'State Market Summary'!$C$4:$C$54) -> 200 | H13: =SUMIF('State Market Summary'!$T$4:$T$54,"T10",'State Market Summary'!$N$4:$N$54) -> 274 | I13: =SUMIF('State Market Summary'!$T$4:$T$54,"T10",'State Market Summary'!$O$4:$O$54) -> 81 | J13: 1 | K13: =IF(J13=0,"unstaffed",ROUND(F13/J13,0)) -> 664 | L13: =IF(J13=0,"unstaffed",ROUND(G13/J13,1)) -> 200 | M13: =H13/F13 -> 0.4126506 | N13: 995376 | O13: 67472 | P13: 29.2 | Q13: =IF(J13=0,"unstaffed",ROUND((20*100*(K13-MIN($K$4:$K$28))/(MAX($K$4:$K$28)-MIN($K$4:$K$28))+60*100*(L13-MIN($L$4:$L$28))/(MAX($L$4:$L$28)-MIN($L$4:$L$28))+10*100*(N13-MIN($N$4:$N$28))/(MAX($N$4:$N$28)-MIN($N$4:$N$28))+10*100*(O13-MIN($O$4:$O$28))/(MAX($O$4:$O$28)-MIN($O$4:$O$28)))/100,1)) -> 39.7 | R13: =IF(J13=0,"n/a",RANK(Q13,$Q$4:$Q$28)) -> 13 | S13: =IF(J13=0,4,IF(R13<=7,1,IF(R13<=12,2,IF(R13<=19,3,4)))) -> 3
E14: T11 GA | F14: =SUMIF('State Market Summary'!$T$4:$T$54,"T11",'State Market Summary'!$B$4:$B$54) -> 683 | G14: =SUMIF('State Market Summary'!$T$4:$T$54,"T11",'State Market Summary'!$C$4:$C$54) -> 220 | H14: =SUMIF('State Market Summary'!$T$4:$T$54,"T11",'State Market Summary'!$N$4:$N$54) -> 122 | I14: =SUMIF('State Market Summary'!$T$4:$T$54,"T11",'State Market Summary'!$O$4:$O$54) -> 49 | J14: 1 | K14: =IF(J14=0,"unstaffed",ROUND(F14/J14,0)) -> 683 | L14: =IF(J14=0,"unstaffed",ROUND(G14/J14,1)) -> 220 | M14: =H14/F14 -> 0.17862372 | N14: 1070611 | O14: 75694 | P14: 33.4 | Q14: =IF(J14=0,"unstaffed",ROUND((20*100*(K14-MIN($K$4:$K$28))/(MAX($K$4:$K$28)-MIN($K$4:$K$28))+60*100*(L14-MIN($L$4:$L$28))/(MAX($L$4:$L$28)-MIN($L$4:$L$28))+10*100*(N14-MIN($N$4:$N$28))/(MAX($N$4:$N$28)-MIN($N$4:$N$28))+10*100*(O14-MIN($O$4:$O$28))/(MAX($O$4:$O$28)-MIN($O$4:$O$28)))/100,1)) -> 47.6 | R14: =IF(J14=0,"n/a",RANK(Q14,$Q$4:$Q$28)) -> 6 | S14: =IF(J14=0,4,IF(R14<=7,1,IF(R14<=12,2,IF(R14<=19,3,4)))) -> 1
E15: T12 WA-OR-AK | F15: =SUMIF('State Market Summary'!$T$4:$T$54,"T12",'State Market Summary'!$B$4:$B$54) -> 734 | G15: =SUMIF('State Market Summary'!$T$4:$T$54,"T12",'State Market Summary'!$C$4:$C$54) -> 225 | H15: =SUMIF('State Market Summary'!$T$4:$T$54,"T12",'State Market Summary'!$N$4:$N$54) -> 383 | I15: =SUMIF('State Market Summary'!$T$4:$T$54,"T12",'State Market Summary'!$O$4:$O$54) -> 112 | J15: 1 | K15: =IF(J15=0,"unstaffed",ROUND(F15/J15,0)) -> 734 | L15: =IF(J15=0,"unstaffed",ROUND(G15/J15,1)) -> 225 | M15: =H15/F15 -> 0.52179837 | N15: 1119028 | O15: 90198 | P15: 36.3 | Q15: =IF(J15=0,"unstaffed",ROUND((20*100*(K15-MIN($K$4:$K$28))/(MAX($K$4:$K$28)-MIN($K$4:$K$28))+60*100*(L15-MIN($L$4:$L$28))/(MAX($L$4:$L$28)-MIN($L$4:$L$28))+10*100*(N15-MIN($N$4:$N$28))/(MAX($N$4:$N$28)-MIN($N$4:$N$28))+10*100*(O15-MIN($O$4:$O$28))/(MAX($O$4:$O$28)-MIN($O$4:$O$28)))/100,1)) -> 54.6 | R15: =IF(J15=0,"n/a",RANK(Q15,$Q$4:$Q$28)) -> 5 | S15: =IF(J15=0,4,IF(R15<=7,1,IF(R15<=12,2,IF(R15<=19,3,4)))) -> 1
E16: T13 NC | F16: =SUMIF('State Market Summary'!$T$4:$T$54,"T13",'State Market Summary'!$B$4:$B$54) -> 779 | G16: =SUMIF('State Market Summary'!$T$4:$T$54,"T13",'State Market Summary'!$C$4:$C$54) -> 181 | H16: =SUMIF('State Market Summary'!$T$4:$T$54,"T13",'State Market Summary'!$N$4:$N$54) -> 306 | I16: =SUMIF('State Market Summary'!$T$4:$T$54,"T13",'State Market Summary'!$O$4:$O$54) -> 71 | J16: 1 | K16: =IF(J16=0,"unstaffed",ROUND(F16/J16,0)) -> 779 | L16: =IF(J16=0,"unstaffed",ROUND(G16/J16,1)) -> 181 | M16: =H16/F16 -> 0.3928113 | N16: 975468 | O16: 70436 | P16: 34 | Q16: =IF(J16=0,"unstaffed",ROUND((20*100*(K16-MIN($K$4:$K$28))/(MAX($K$4:$K$28)-MIN($K$4:$K$28))+60*100*(L16-MIN($L$4:$L$28))/(MAX($L$4:$L$28)-MIN($L$4:$L$28))+10*100*(N16-MIN($N$4:$N$28))/(MAX($N$4:$N$28)-MIN($N$4:$N$28))+10*100*(O16-MIN($O$4:$O$28))/(MAX($O$4:$O$28)-MIN($O$4:$O$28)))/100,1)) -> 39.9 | R16: =IF(J16=0,"n/a",RANK(Q16,$Q$4:$Q$28)) -> 12 | S16: =IF(J16=0,4,IF(R16<=7,1,IF(R16<=12,2,IF(R16<=19,3,4)))) -> 2
E17: T14 KS-OK-NE-NM | F17: =SUMIF('State Market Summary'!$T$4:$T$54,"T14",'State Market Summary'!$B$4:$B$54) -> 597 | G17: =SUMIF('State Market Summary'!$T$4:$T$54,"T14",'State Market Summary'!$C$4:$C$54) -> 198 | H17: =SUMIF('State Market Summary'!$T$4:$T$54,"T14",'State Market Summary'!$N$4:$N$54) -> 205 | I17: =SUMIF('State Market Summary'!$T$4:$T$54,"T14",'State Market Summary'!$O$4:$O$54) -> 79 | J17: 1 | K17: =IF(J17=0,"unstaffed",ROUND(F17/J17,0)) -> 597 | L17: =IF(J17=0,"unstaffed",ROUND(G17/J17,1)) -> 198 | M17: =H17/F17 -> 0.34338358 | N17: 1097099 | O17: 68598 | P17: 30.5 | Q17: =IF(J17=0,"unstaffed",ROUND((20*100*(K17-MIN($K$4:$K$28))/(MAX($K$4:$K$28)-MIN($K$4:$K$28))+60*100*(L17-MIN($L$4:$L$28))/(MAX($L$4:$L$28)-MIN($L$4:$L$28))+10*100*(N17-MIN($N$4:$N$28))/(MAX($N$4:$N$28)-MIN($N$4:$N$28))+10*100*(O17-MIN($O$4:$O$28))/(MAX($O$4:$O$28)-MIN($O$4:$O$28)))/100,1)) -> 37.5 | R17: =IF(J17=0,"n/a",RANK(Q17,$Q$4:$Q$28)) -> 15 | S17: =IF(J17=0,4,IF(R17<=7,1,IF(R17<=12,2,IF(R17<=19,3,4)))) -> 3
E18: T15 AZ-NV-ID-MT | F18: =SUMIF('State Market Summary'!$T$4:$T$54,"T15",'State Market Summary'!$B$4:$B$54) -> 594 | G18: =SUMIF('State Market Summary'!$T$4:$T$54,"T15",'State Market Summary'!$C$4:$C$54) -> 231 | H18: =SUMIF('State Market Summary'!$T$4:$T$54,"T15",'State Market Summary'!$N$4:$N$54) -> 199 | I18: =SUMIF('State Market Summary'!$T$4:$T$54,"T15",'State Market Summary'!$O$4:$O$54) -> 83 | J18: 1 | K18: =IF(J18=0,"unstaffed",ROUND(F18/J18,0)) -> 594 | L18: =IF(J18=0,"unstaffed",ROUND(G18/J18,1)) -> 231 | M18: =H18/F18 -> 0.33501684 | N18: 1257732 | O18: 75026 | P18: 30 | Q18: =IF(J18=0,"unstaffed",ROUND((20*100*(K18-MIN($K$4:$K$28))/(MAX($K$4:$K$28)-MIN($K$4:$K$28))+60*100*(L18-MIN($L$4:$L$28))/(MAX($L$4:$L$28)-MIN($L$4:$L$28))+10*100*(N18-MIN($N$4:$N$28))/(MAX($N$4:$N$28)-MIN($N$4:$N$28))+10*100*(O18-MIN($O$4:$O$28))/(MAX($O$4:$O$28)-MIN($O$4:$O$28)))/100,1)) -> 47.6 | R18: =IF(J18=0,"n/a",RANK(Q18,$Q$4:$Q$28)) -> 6 | S18: =IF(J18=0,4,IF(R18<=7,1,IF(R18<=12,2,IF(R18<=19,3,4)))) -> 1
E19: T16 CO-UT | F19: =SUMIF('State Market Summary'!$T$4:$T$54,"T16",'State Market Summary'!$B$4:$B$54) -> 550 | G19: =SUMIF('State Market Summary'!$T$4:$T$54,"T16",'State Market Summary'!$C$4:$C$54) -> 185 | H19: =SUMIF('State Market Summary'!$T$4:$T$54,"T16",'State Market Summary'!$N$4:$N$54) -> 202 | I19: =SUMIF('State Market Summary'!$T$4:$T$54,"T16",'State Market Summary'!$O$4:$O$54) -> 79 | J19: 1 | K19: =IF(J19=0,"unstaffed",ROUND(F19/J19,0)) -> 550 | L19: =IF(J19=0,"unstaffed",ROUND(G19/J19,1)) -> 185 | M19: =H19/F19 -> 0.36727273 | N19: 915366 | O19: 91862 | P19: 40.7 | Q19: =IF(J19=0,"unstaffed",ROUND((20*100*(K19-MIN($K$4:$K$28))/(MAX($K$4:$K$28)-MIN($K$4:$K$28))+60*100*(L19-MIN($L$4:$L$28))/(MAX($L$4:$L$28)-MIN($L$4:$L$28))+10*100*(N19-MIN($N$4:$N$28))/(MAX($N$4:$N$28)-MIN($N$4:$N$28))+10*100*(O19-MIN($O$4:$O$28))/(MAX($O$4:$O$28)-MIN($O$4:$O$28)))/100,1)) -> 38.3 | R19: =IF(J19=0,"n/a",RANK(Q19,$Q$4:$Q$28)) -> 14 | S19: =IF(J19=0,4,IF(R19<=7,1,IF(R19<=12,2,IF(R19<=19,3,4)))) -> 3
E20: T17 IL | F20: =SUMIF('State Market Summary'!$T$4:$T$54,"T17",'State Market Summary'!$B$4:$B$54) -> 718 | G20: =SUMIF('State Market Summary'!$T$4:$T$54,"T17",'State Market Summary'!$C$4:$C$54) -> 241 | H20: =SUMIF('State Market Summary'!$T$4:$T$54,"T17",'State Market Summary'!$N$4:$N$54) -> 348 | I20: =SUMIF('State Market Summary'!$T$4:$T$54,"T17",'State Market Summary'!$O$4:$O$54) -> 81 | J20: 1 | K20: =IF(J20=0,"unstaffed",ROUND(F20/J20,0)) -> 718 | L20: =IF(J20=0,"unstaffed",ROUND(G20/J20,1)) -> 241 | M20: =H20/F20 -> 0.48467967 | N20: 1191812 | O20: 84033 | P20: 36.3 | Q20: =IF(J20=0,"unstaffed",ROUND((20*100*(K20-MIN($K$4:$K$28))/(MAX($K$4:$K$28)-MIN($K$4:$K$28))+60*100*(L20-MIN($L$4:$L$28))/(MAX($L$4:$L$28)-MIN($L$4:$L$28))+10*100*(N20-MIN($N$4:$N$28))/(MAX($N$4:$N$28)-MIN($N$4:$N$28))+10*100*(O20-MIN($O$4:$O$28))/(MAX($O$4:$O$28)-MIN($O$4:$O$28)))/100,1)) -> 56.5 | R20: =IF(J20=0,"n/a",RANK(Q20,$Q$4:$Q$28)) -> 4 | S20: =IF(J20=0,4,IF(R20<=7,1,IF(R20<=12,2,IF(R20<=19,3,4)))) -> 1
E21: T18 AL-MS | F21: =SUMIF('State Market Summary'!$T$4:$T$54,"T18",'State Market Summary'!$B$4:$B$54) -> 462 | G21: =SUMIF('State Market Summary'!$T$4:$T$54,"T18",'State Market Summary'!$C$4:$C$54) -> 174 | H21: =SUMIF('State Market Summary'!$T$4:$T$54,"T18",'State Market Summary'!$N$4:$N$54) -> 89 | I21: =SUMIF('State Market Summary'!$T$4:$T$54,"T18",'State Market Summary'!$O$4:$O$54) -> 37 | J21: 1 | K21: =IF(J21=0,"unstaffed",ROUND(F21/J21,0)) -> 462 | L21: =IF(J21=0,"unstaffed",ROUND(G21/J21,1)) -> 174 | M21: =H21/F21 -> 0.19264069 | N21: 772926 | O21: 60048 | P21: 26.1 | Q21: =IF(J21=0,"unstaffed",ROUND((20*100*(K21-MIN($K$4:$K$28))/(MAX($K$4:$K$28)-MIN($K$4:$K$28))+60*100*(L21-MIN($L$4:$L$28))/(MAX($L$4:$L$28)-MIN($L$4:$L$28))+10*100*(N21-MIN($N$4:$N$28))/(MAX($N$4:$N$28)-MIN($N$4:$N$28))+10*100*(O21-MIN($O$4:$O$28))/(MAX($O$4:$O$28)-MIN($O$4:$O$28)))/100,1)) -> 23.8 | R21: =IF(J21=0,"n/a",RANK(Q21,$Q$4:$Q$28)) -> 21 | S21: =IF(J21=0,4,IF(R21<=7,1,IF(R21<=12,2,IF(R21<=19,3,4)))) -> 4
E22: T19 LA-AR | F22: =SUMIF('State Market Summary'!$T$4:$T$54,"T19",'State Market Summary'!$B$4:$B$54) -> 477 | G22: =SUMIF('State Market Summary'!$T$4:$T$54,"T19",'State Market Summary'!$C$4:$C$54) -> 176 | H22: =SUMIF('State Market Summary'!$T$4:$T$54,"T19",'State Market Summary'!$N$4:$N$54) -> 201 | I22: =SUMIF('State Market Summary'!$T$4:$T$54,"T19",'State Market Summary'!$O$4:$O$54) -> 69 | J22: 1 | K22: =IF(J22=0,"unstaffed",ROUND(F22/J22,0)) -> 477 | L22: =IF(J22=0,"unstaffed",ROUND(G22/J22,1)) -> 176 | M22: =H22/F22 -> 0.42138365 | N22: 739152 | O22: 59699 | P22: 25.6 | Q22: =IF(J22=0,"unstaffed",ROUND((20*100*(K22-MIN($K$4:$K$28))/(MAX($K$4:$K$28)-MIN($K$4:$K$28))+60*100*(L22-MIN($L$4:$L$28))/(MAX($L$4:$L$28)-MIN($L$4:$L$28))+10*100*(N22-MIN($N$4:$N$28))/(MAX($N$4:$N$28)-MIN($N$4:$N$28))+10*100*(O22-MIN($O$4:$O$28))/(MAX($O$4:$O$28)-MIN($O$4:$O$28)))/100,1)) -> 24.6 | R22: =IF(J22=0,"n/a",RANK(Q22,$Q$4:$Q$28)) -> 19 | S22: =IF(J22=0,4,IF(R22<=7,1,IF(R22<=12,2,IF(R22<=19,3,4)))) -> 3
E23: T20 IN | F23: =SUMIF('State Market Summary'!$T$4:$T$54,"T20",'State Market Summary'!$B$4:$B$54) -> 442 | G23: =SUMIF('State Market Summary'!$T$4:$T$54,"T20",'State Market Summary'!$C$4:$C$54) -> 111 | H23: =SUMIF('State Market Summary'!$T$4:$T$54,"T20",'State Market Summary'!$N$4:$N$54) -> 173 | I23: =SUMIF('State Market Summary'!$T$4:$T$54,"T20",'State Market Summary'!$O$4:$O$54) -> 48 | J23: 1 | K23: =IF(J23=0,"unstaffed",ROUND(F23/J23,0)) -> 442 | L23: =IF(J23=0,"unstaffed",ROUND(G23/J23,1)) -> 111 | M23: =H23/F23 -> 0.39140271 | N23: 663850 | O23: 70489 | P23: 28.5 | Q23: =IF(J23=0,"unstaffed",ROUND((20*100*(K23-MIN($K$4:$K$28))/(MAX($K$4:$K$28)-MIN($K$4:$K$28))+60*100*(L23-MIN($L$4:$L$28))/(MAX($L$4:$L$28)-MIN($L$4:$L$28))+10*100*(N23-MIN($N$4:$N$28))/(MAX($N$4:$N$28)-MIN($N$4:$N$28))+10*100*(O23-MIN($O$4:$O$28))/(MAX($O$4:$O$28)-MIN($O$4:$O$28)))/100,1)) -> 10.2 | R23: =IF(J23=0,"n/a",RANK(Q23,$Q$4:$Q$28)) -> 23 | S23: =IF(J23=0,4,IF(R23<=7,1,IF(R23<=12,2,IF(R23<=19,3,4)))) -> 4
E24: T21 VA | F24: =SUMIF('State Market Summary'!$T$4:$T$54,"T21",'State Market Summary'!$B$4:$B$54) -> 478 | G24: =SUMIF('State Market Summary'!$T$4:$T$54,"T21",'State Market Summary'!$C$4:$C$54) -> 137 | H24: =SUMIF('State Market Summary'!$T$4:$T$54,"T21",'State Market Summary'!$N$4:$N$54) -> 241 | I24: =SUMIF('State Market Summary'!$T$4:$T$54,"T21",'State Market Summary'!$O$4:$O$54) -> 49 | J24: 1 | K24: =IF(J24=0,"unstaffed",ROUND(F24/J24,0)) -> 478 | L24: =IF(J24=0,"unstaffed",ROUND(G24/J24,1)) -> 137 | M24: =H24/F24 -> 0.5041841 | N24: 794462 | O24: 97828 | P24: 41.2 | Q24: =IF(J24=0,"unstaffed",ROUND((20*100*(K24-MIN($K$4:$K$28))/(MAX($K$4:$K$28)-MIN($K$4:$K$28))+60*100*(L24-MIN($L$4:$L$28))/(MAX($L$4:$L$28)-MIN($L$4:$L$28))+10*100*(N24-MIN($N$4:$N$28))/(MAX($N$4:$N$28)-MIN($N$4:$N$28))+10*100*(O24-MIN($O$4:$O$28))/(MAX($O$4:$O$28)-MIN($O$4:$O$28)))/100,1)) -> 25.3 | R24: =IF(J24=0,"n/a",RANK(Q24,$Q$4:$Q$28)) -> 18 | S24: =IF(J24=0,4,IF(R24<=7,1,IF(R24<=12,2,IF(R24<=19,3,4)))) -> 3
E25: T22 MD-WV-DE-DC | F25: =SUMIF('State Market Summary'!$T$4:$T$54,"T22",'State Market Summary'!$B$4:$B$54) -> 489 | G25: =SUMIF('State Market Summary'!$T$4:$T$54,"T22",'State Market Summary'!$C$4:$C$54) -> 168 | H25: =SUMIF('State Market Summary'!$T$4:$T$54,"T22",'State Market Summary'!$N$4:$N$54) -> 199 | I25: =SUMIF('State Market Summary'!$T$4:$T$54,"T22",'State Market Summary'!$O$4:$O$54) -> 78 | J25: 1 | K25: =IF(J25=0,"unstaffed",ROUND(F25/J25,0)) -> 489 | L25: =IF(J25=0,"unstaffed",ROUND(G25/J25,1)) -> 168 | M25: =H25/F25 -> 0.40695297 | N25: 860620 | O25: 94114 | P25: 39.1 | Q25: =IF(J25=0,"unstaffed",ROUND((20*100*(K25-MIN($K$4:$K$28))/(MAX($K$4:$K$28)-MIN($K$4:$K$28))+60*100*(L25-MIN($L$4:$L$28))/(MAX($L$4:$L$28)-MIN($L$4:$L$28))+10*100*(N25-MIN($N$4:$N$28))/(MAX($N$4:$N$28)-MIN($N$4:$N$28))+10*100*(O25-MIN($O$4:$O$28))/(MAX($O$4:$O$28)-MIN($O$4:$O$28)))/100,1)) -> 32.4 | R25: =IF(J25=0,"n/a",RANK(Q25,$Q$4:$Q$28)) -> 17 | S25: =IF(J25=0,4,IF(R25<=7,1,IF(R25<=12,2,IF(R25<=19,3,4)))) -> 3
E26: T23 TN | F26: =SUMIF('State Market Summary'!$T$4:$T$54,"T23",'State Market Summary'!$B$4:$B$54) -> 401 | G26: =SUMIF('State Market Summary'!$T$4:$T$54,"T23",'State Market Summary'!$C$4:$C$54) -> 124 | H26: =SUMIF('State Market Summary'!$T$4:$T$54,"T23",'State Market Summary'!$N$4:$N$54) -> 159 | I26: =SUMIF('State Market Summary'!$T$4:$T$54,"T23",'State Market Summary'!$O$4:$O$54) -> 44 | J26: 1 | K26: =IF(J26=0,"unstaffed",ROUND(F26/J26,0)) -> 401 | L26: =IF(J26=0,"unstaffed",ROUND(G26/J26,1)) -> 124 | M26: =H26/F26 -> 0.39650873 | N26: 634143 | O26: 67976 | P26: 29.8 | Q26: =IF(J26=0,"unstaffed",ROUND((20*100*(K26-MIN($K$4:$K$28))/(MAX($K$4:$K$28)-MIN($K$4:$K$28))+60*100*(L26-MIN($L$4:$L$28))/(MAX($L$4:$L$28)-MIN($L$4:$L$28))+10*100*(N26-MIN($N$4:$N$28))/(MAX($N$4:$N$28)-MIN($N$4:$N$28))+10*100*(O26-MIN($O$4:$O$28))/(MAX($O$4:$O$28)-MIN($O$4:$O$28)))/100,1)) -> 11.2 | R26: =IF(J26=0,"n/a",RANK(Q26,$Q$4:$Q$28)) -> 22 | S26: =IF(J26=0,4,IF(R26<=7,1,IF(R26<=12,2,IF(R26<=19,3,4)))) -> 4
E27: T24 IA-SD-ND-WY | F27: =SUMIF('State Market Summary'!$T$4:$T$54,"T24",'State Market Summary'!$B$4:$B$54) -> 345 | G27: =SUMIF('State Market Summary'!$T$4:$T$54,"T24",'State Market Summary'!$C$4:$C$54) -> 111 | H27: =SUMIF('State Market Summary'!$T$4:$T$54,"T24",'State Market Summary'!$N$4:$N$54) -> 168 | I27: =SUMIF('State Market Summary'!$T$4:$T$54,"T24",'State Market Summary'!$O$4:$O$54) -> 55 | J27: 1 | K27: =IF(J27=0,"unstaffed",ROUND(F27/J27,0)) -> 345 | L27: =IF(J27=0,"unstaffed",ROUND(G27/J27,1)) -> 111 | M27: =H27/F27 -> 0.48695652 | N27: 528815 | O27: 73245 | P27: 30.7 | Q27: =IF(J27=0,"unstaffed",ROUND((20*100*(K27-MIN($K$4:$K$28))/(MAX($K$4:$K$28)-MIN($K$4:$K$28))+60*100*(L27-MIN($L$4:$L$28))/(MAX($L$4:$L$28)-MIN($L$4:$L$28))+10*100*(N27-MIN($N$4:$N$28))/(MAX($N$4:$N$28)-MIN($N$4:$N$28))+10*100*(O27-MIN($O$4:$O$28))/(MAX($O$4:$O$28)-MIN($O$4:$O$28)))/100,1)) -> 7.1 | R27: =IF(J27=0,"n/a",RANK(Q27,$Q$4:$Q$28)) -> 24 | S27: =IF(J27=0,4,IF(R27<=7,1,IF(R27<=12,2,IF(R27<=19,3,4)))) -> 4
E28: T25 SC | F28: =SUMIF('State Market Summary'!$T$4:$T$54,"T25",'State Market Summary'!$B$4:$B$54) -> 364 | G28: =SUMIF('State Market Summary'!$T$4:$T$54,"T25",'State Market Summary'!$C$4:$C$54) -> 97 | H28: =SUMIF('State Market Summary'!$T$4:$T$54,"T25",'State Market Summary'!$N$4:$N$54) -> 149 | I28: =SUMIF('State Market Summary'!$T$4:$T$54,"T25",'State Market Summary'!$O$4:$O$54) -> 28 | J28: 1 | K28: =IF(J28=0,"unstaffed",ROUND(F28/J28,0)) -> 364 | L28: =IF(J28=0,"unstaffed",ROUND(G28/J28,1)) -> 97 | M28: =H28/F28 -> 0.40934066 | N28: 473826 | O28: 65973 | P28: 30.6 | Q28: =IF(J28=0,"unstaffed",ROUND((20*100*(K28-MIN($K$4:$K$28))/(MAX($K$4:$K$28)-MIN($K$4:$K$28))+60*100*(L28-MIN($L$4:$L$28))/(MAX($L$4:$L$28)-MIN($L$4:$L$28))+10*100*(N28-MIN($N$4:$N$28))/(MAX($N$4:$N$28)-MIN($N$4:$N$28))+10*100*(O28-MIN($O$4:$O$28))/(MAX($O$4:$O$28)-MIN($O$4:$O$28)))/100,1)) -> 2.3 | R28: =IF(J28=0,"n/a",RANK(Q28,$Q$4:$Q$28)) -> 25 | S28: =IF(J28=0,4,IF(R28<=7,1,IF(R28<=12,2,IF(R28<=19,3,4)))) -> 4
E29: TOTAL | F29: =SUM(F4:F28) -> 18405 | G29: =SUM(G4:G28) -> 5862 | H29: =SUM(H4:H28) -> 7524 | I29: =SUM(I4:I28) -> 2208 | J29: =SUM(J4:J28) -> 30 | K29: =ROUND(F29/J29,0) -> 614 | L29: =ROUND(G29/J29,1) -> 195.4 | M29: =H29/F29 -> 0.40880196
E31: Score = min-max normalization (0-100 across staffed territories) of All MDs/Rep (20%), All Clinics/Rep (60%), Women 25-44 (10%), Median Income (10%); Education 0% (displayed, not scored). Blue cells are inputs: Reps carries the 28-rep hard-cap allocation; Women 25-44 / Median Income / Education carried from v3 Territory Plan unchanged (v3 census data-quality caveats apply). All MD/clinic counts (F-I) are sums of member states from Waterfall A rev1 labeled columns only; stray unlabeled scratch columns in the source were excluded.
E33: ACADEMIC SHARE (column M) = All Academic/Group MDs / All MDs (column H / column F). Percent of a territory's physician universe practicing in academic, hospital/system, or group settings versus private practice; MSO-managed practices (UWH, Axia) are RECLASSIFIED to Private per direction — see MSO Reclassification tab. Classification otherwise per the Data Request waterfall method (CMS facility IDs and hospital/system/university name tokens). National benchmark: 7,524 / 18,405 = 40.9%. Display only (0% score weight). Note: metro-level academic splits exist only for the >=10 tier; no row-level data exists below volume 10.

Sheet Academic by Metro (ge10)
A1: UNIVERSE: >=10 volume tier ONLY — NOT the full ALL-MD universe. Source: Waterfall A rev1 row-level tabs, with the 106 MSO physicians reclassified Academic->Private (see MSO Reclassification tab; adjusted cells highlighted). Metro = city as recorded; no MSA grouping until the Phase 2 clinic-address append. Puerto Rico excluded. TOTAL row ties to Waterfall A >=10 totals exactly: 1,412 academic / 2,989 private / 4,401.
A2: State | B2: Metro (city as recorded) | C2: Territory | D2: Academic/Group MDs (>=10) | E2: Private MDs (>=10) | F2: Total MDs (>=10) | G2: Academic Share (>=10)
A3: AK | B3: Anchorage | C3: T12 | D3: 0 | E3: 8 | F3: =D3+E3 -> 8 | G3: =IF(F3=0,"n/a",D3/F3) -> 0
A4: AK | B4: Fairbanks | C4: T12 | D4: 0 | E4: 3 | F4: =D4+E4 -> 3 | G4: =IF(F4=0,"n/a",D4/F4) -> 0
A5: AK | B5: Homer | C5: T12 | D5: 0 | E5: 1 | F5: =D5+E5 -> 1 | G5: =IF(F5=0,"n/a",D5/F5) -> 0
A6: AK | B6: Palmer | C6: T12 | D6: 0 | E6: 1 | F6: =D6+E6 -> 1 | G6: =IF(F6=0,"n/a",D6/F6) -> 0
A7: AK | B7: Wasilla | C7: T12 | D7: 0 | E7: 1 | F7: =D7+E7 -> 1 | G7: =IF(F7=0,"n/a",D7/F7) -> 0
A8: AL | B8: Birmingham | C8: T18 | D8: 4 | E8: 14 | F8: =D8+E8 -> 18 | G8: =IF(F8=0,"n/a",D8/F8) -> 0.22222222
A9: AL | B9: Mobile | C9: T18 | D9: 1 | E9: 11 | F9: =D9+E9 -> 12 | G9: =IF(F9=0,"n/a",D9/F9) -> 0.083333333
A10: AL | B10: Huntsville | C10: T18 | D10: 1 | E10: 10 | F10: =D10+E10 -> 11 | G10: =IF(F10=0,"n/a",D10/F10) -> 0.090909091
A11: AL | B11: Montgomery | C11: T18 | D11: 0 | E11: 10 | F11: =D11+E11 -> 10 | G11: =IF(F11=0,"n/a",D11/F11) -> 0
A12: AL | B12: Dothan | C12: T18 | D12: 3 | E12: 5 | F12: =D12+E12 -> 8 | G12: =IF(F12=0,"n/a",D12/F12) -> 0.375
A13: AL | B13: Anniston | C13: T18 | D13: 0 | E13: 4 | F13: =D13+E13 -> 4 | G13: =IF(F13=0,"n/a",D13/F13) -> 0
A14: AL | B14: Auburn | C14: T18 | D14: 0 | E14: 4 | F14: =D14+E14 -> 4 | G14: =IF(F14=0,"n/a",D14/F14) -> 0
... A1281: WY | B1281: Laramie | C1281: T24 | D1281: 1 | E1281: 1 | F1281: =D1281+E1281 -> 2 | G1281: =IF(F1281=0,"n/a",D1281/F1281) -> 0.5
A1282: TOTAL | D1282: =SUM(D3:D1281) -> 1412 | E1282: =SUM(E3:E1281) -> 2989 | F1282: =SUM(F3:F1281) -> 4401 | G1282: =IF(F1282=0,"n/a",D1282/F1282) -> 0.32083617

Sheet v4 Reference (pre-MSO)
A1: v4 REFERENCE — numbers BEFORE MSO removal: Waterfall A rev1 canonical, exactly as used in v4. Retained for reference only; every live tab in this v7 workbook uses the ex-MSO numbers (see MSO Reclassification tab for the deltas). Headline v4 totals: All MDs 18,405 | All Clinics 5,862 | >=10 MDs 4,401 | >=20 MDs 1,476 | Private ALL 10,775 | Academic/Group ALL 7,630. NV Private All MDs shown as 115 = Total - Academic (source cell reads 304, inconsistent with its own totals).
B2: TOTAL | H2: PRIVATE | N2: ACADEMIC/GROUP
A3: State | B3: All MDs | C3: All Clinics | D3: MDs >=10 | E3: Clinics >=10 | F3: MDs >=20 | G3: Clinics >=20 | H3: All MDs | I3: All Clinics | J3: MDs >=10 | K3: Clinics >=10 | L3: MDs >=20 | M3: Clinics >=20 | N3: All MDs | O3: All Clinics | P3: MDs >=10 | Q3: Clinics >=10 | R3: MDs >=20 | S3: Clinics >=20
A4: AK | B4: 50 | C4: 25 | D4: 14 | E4: 10 | F4: 8 | G4: 7 | H4: 37 | I4: 17 | J4: 14 | K4: 10 | L4: 8 | M4: 7 | N4: 13 | O4: 8 | P4: 0 | Q4: 0 | R4: 0 | S4: 0
